<?xml version="1.0"?>
<robot xmlns:xacro="http://www.ros.org/wiki/xacro">

    <xacro:macro name="wheel" params="prefix left_back_link left_front_link left_mid_link right_back_link right_front_link right_mid_link">
        

        <link name="${prefix}left_back_wheel_link">
            <collision name="left_back_wheel_collision">
                <origin rpy="0.00000 0.00000 0.00000" xyz="-0.00000 0.00000 0.00000"/>
                <geometry>
                    <mesh filename="package://albor_description/meshes/dae/Torus.010.dae" scale="0.40000 0.40000 1.00000"/>
                </geometry>
                <surface>
                    <friction>
                        <ode>
                            <mu>5.000000</mu>
                            <mu2>5.00000</mu2>
                            <fdir1>0.00000 0.000000 1.000000</fdir1>
                            <slip1>0.500000</slip1>
                            <slip2>0.500000</slip2>
                        </ode>
                    </friction>
                </surface>
            </collision>
            <inertial>
                <inertia ixx="1.17295" ixy="0.00000" ixz="-0.00000" iyy="0.70953" iyz="-0.00000" izz="0.70953"/>
                <origin rpy="0.00000 0.00000 0.00000" xyz="-0.00000 0.00000 0.00000"/>
                <mass value="10.00000"/>
            </inertial>
            <visual name="left_back_wheel">
                <origin rpy="0.00000 0.00000 0.00000" xyz="-0.00000 0.00000 0.00000"/>
                <material name="Material.016"/>
                <geometry>
                    <mesh filename="package://albor_description/meshes/dae/Torus.010.dae" scale="0.40000 0.40000 1.00000"/>
                </geometry>
            </visual>
        </link>
        
        <link name="${prefix}left_front_wheel_link">
            <collision name="left_front_wheel_collision">
                <origin rpy="0.00000 0.00000 0.00000" xyz="0.00000 0.00000 0.00000"/>
                <geometry>
                <mesh filename="package://albor_description/meshes/dae/Torus.004.dae" scale="0.40000 0.40000 1.00000"/>
                </geometry>
                <surface>
                    <friction>
                        <ode>
                            <mu>5.000000</mu>
                            <mu2>5.00000</mu2>
                            <fdir1>0.00000 0.000000 1.000000</fdir1>
                            <slip1>0.500000</slip1>
                            <slip2>0.500000</slip2>
                        </ode>
                    </friction>
                </surface>
            </collision>
            <inertial>
                <inertia ixx="1.17295" ixy="0.00000" ixz="-0.00000" iyy="0.70953" iyz="-0.00000" izz="0.70953"/>
                <origin rpy="0.00000 0.00000 0.00000" xyz="-0.00000 -0.00000 0.00000"/>
                <mass value="10.00000"/>
            </inertial>
            <visual name="left_front_wheel">
                <origin rpy="0.00000 -0.00000 0.00000" xyz="0.00000 0.00000 0.00000"/>
                <material name="Material.017"/>
                <geometry>
                <mesh filename="package://albor_description/meshes/dae/Torus.004.dae" scale="0.40000 0.40000 1.00000"/>
                </geometry>
            </visual>
        </link>
        
        <link name="${prefix}left_mid_wheel_link">
            <collision name="left_mid_wheel_collision">
                <origin rpy="0.00000 0.00000 0.00000" xyz="0.00000 0.00000 0.00000"/>
                <geometry>
                <mesh filename="package://albor_description/meshes/dae/Torus.008.dae" scale="0.40000 0.40000 1.00000"/>
                </geometry>
                <surface>
                    <friction>
                        <ode>
                            <mu>5.000000</mu>
                            <mu2>5.00000</mu2>
                            <fdir1>0.00000 0.000000 1.000000</fdir1>
                            <slip1>0.500000</slip1>
                            <slip2>0.500000</slip2>
                        </ode>
                    </friction>
                </surface>
            </collision>
            <inertial>
                <inertia ixx="1.17295" ixy="0.00000" ixz="-0.00000" iyy="0.70953" iyz="-0.00000" izz="0.70953"/>
                <origin rpy="0.00000 0.00000 0.00000" xyz="0.00000 0.00000 0.00000"/>
                <mass value="10.00000"/>
            </inertial>
            <visual name="left_mid_wheel">
                <origin rpy="0.00000 -0.00000 0.00000" xyz="0.00000 0.00000 0.00000"/>
                <material name="Material.018"/>
                <geometry>
                <mesh filename="package://albor_description/meshes/dae/Torus.008.dae" scale="0.40000 0.40000 1.00000"/>
                </geometry>
            </visual>
        </link>
        
        <link name="${prefix}right_back_wheel_link">
            <collision name="right_back_wheel_collision">
                <origin rpy="0.00000 0.00000 0.00000" xyz="-0.00000 0.00000 -0.00000"/>
                <geometry>
                <mesh filename="package://albor_description/meshes/dae/Torus.011.dae" scale="0.40000 0.40000 1.00000"/>
                </geometry>
                <surface>
                    <friction>
                        <ode>
                            <mu>5.000000</mu>
                            <mu2>5.00000</mu2>
                            <fdir1>0.00000 0.000000 1.000000</fdir1>
                            <slip1>0.500000</slip1>
                            <slip2>0.500000</slip2>
                        </ode>
                    </friction>
                </surface>
            </collision>
            <inertial>
                <inertia ixx="1.17295" ixy="0.00000" ixz="-0.00000" iyy="0.70953" iyz="-0.00000" izz="0.70953"/>
                <origin rpy="0.00000 0.00000 0.00000" xyz="0.00000 0.00000 0.00000"/>
                <mass value="10.00000"/>
            </inertial>
            <visual name="right_back_wheel">
                <origin rpy="0.00000 0.00000 0.00000" xyz="0.00000 0.00000 0.00000"/>
                <material name="Material.019"/>
                <geometry>
                <mesh filename="package://albor_description/meshes/dae/Torus.011.dae" scale="0.40000 0.40000 1.00000"/>
                </geometry>
            </visual>
        </link>
        
        <link name="${prefix}right_front_wheel_link">
            <collision name="right_front_wheel_collision">
                <origin rpy="0.00000 0.00000 0.00000" xyz="-0.00000 0.00000 -0.00000"/>
                <geometry>
                <mesh filename="package://albor_description/meshes/dae/Torus.dae" scale="0.40000 0.40000 1.00000"/>
                </geometry>
                <surface>
                    <friction>
                        <ode>
                            <mu>5.000000</mu>
                            <mu2>5.00000</mu2>
                            <fdir1>0.00000 0.000000 1.000000</fdir1>
                            <slip1>0.500000</slip1>
                            <slip2>0.500000</slip2>
                        </ode>
                    </friction>
                </surface>
            </collision>
            <inertial>
                <inertia ixx="1.17295" ixy="0.00000" ixz="-0.00000" iyy="0.70953" iyz="-0.00000" izz="0.70953"/>
                <origin rpy="0.00000 0.00000 0.00000" xyz="0.00000 -0.00000 0.00000"/>
                <mass value="10.00000"/>
            </inertial>
            <visual name="right_front_wheel">
                <origin rpy="0.00000 -0.00000 0.00000" xyz="0.00000 0.00000 0.00000"/>
                <material name="Material.020"/>
                <geometry>
                <mesh filename="package://albor_description/meshes/dae/Torus.dae" scale="0.40000 0.40000 1.00000"/>
                </geometry>
            </visual>
        </link>
        
        <link name="${prefix}right_mid_wheel_link">
            <collision name="right_mid_wheel_collision">
                <origin rpy="0.00000 0.00000 0.00000" xyz="0.00000 0.00000 0.00000"/>
                <geometry>
                <mesh filename="package://albor_description/meshes/dae/Torus.009.dae" scale="0.40000 0.40000 1.00000"/>
                </geometry>
                <surface>
                    <friction>
                        <ode>
                            <mu>5.000000</mu>
                            <mu2>5.00000</mu2>
                            <fdir1>0.00000 0.000000 1.000000</fdir1>
                            <slip1>0.500000</slip1>
                            <slip2>0.500000</slip2>
                        </ode>
                    </friction>
                </surface>
            </collision>
            <inertial>
                <inertia ixx="1.17295" ixy="0.00000" ixz="-0.00000" iyy="0.70953" iyz="-0.00000" izz="0.70953"/>
                <origin rpy="0.00000 0.00000 0.00000" xyz="-0.00000 0.00000 0.00000"/>
                <mass value="10.00000"/>
            </inertial>
            <visual name="right_mid_wheel">
                <origin rpy="0.00000 0.00000 0.00000" xyz="-0.00000 0.00000 0.00000"/>
                <material name="Material.021"/>
                <geometry>
                <mesh filename="package://albor_description/meshes/dae/Torus.009.dae" scale="0.40000 0.40000 1.00000"/>
                </geometry>
            </visual>
        </link>

        <joint name="${prefix}left_back_wheel_joint" type="continuous">
            <limit lower="0" upper="0" effort="500.00000" velocity="10.00000"/>
            <origin rpy="0.00000 3.14000 0.00000" xyz="0.00000 0.00000 0.25000"/>
            <parent link="${left_back_link}"/>
            <child link="${prefix}left_back_wheel_link"/>
            <axis xyz="0.00000 0.00000 1.00000"/>
        </joint>

        <transmission name="${prefix}left_back_wheel_joint_trans">
            <type>transmission_interface/SimpleTransmission</type>
            <joint name="${prefix}left_back_wheel_joint">
                <hardwareInterface>hardware_interface/VelocityJointInterface</hardwareInterface>
            </joint>
            <actuator name="${prefix}left_back_wheel_joint_motor">
                <mechanicalReduction>1.0</mechanicalReduction>
            </actuator>
        </transmission>

        <joint name="${prefix}left_front_wheel_joint" type="continuous">
            <limit lower="0" upper="0" effort="500.00000" velocity="10.00000"/>
            <origin rpy="0.00000 3.14000 0.00000" xyz="0.00000 0.00000 0.25000"/>
            <parent link="${left_front_link}"/>
            <child link="${prefix}left_front_wheel_link"/>
            <axis xyz="0.00000 0.00000 1.00000"/>
        </joint>
        <transmission name="${prefix}left_front_wheel_joint_trans">
            <type>transmission_interface/SimpleTransmission</type>
            <joint name="${prefix}left_front_wheel_joint">
                <hardwareInterface>hardware_interface/VelocityJointInterface</hardwareInterface>
            </joint>
            <actuator name="${prefix}left_front_wheel_joint_motor">
                <mechanicalReduction>1.0</mechanicalReduction>
            </actuator>
        </transmission>

        <joint name="${prefix}left_mid_wheel_joint" type="continuous">
            <limit lower="0" upper="0" effort="500.00000" velocity="10.00000"/>
            <origin rpy="0.00000 3.14000 0.00000" xyz="0.00000 0.00000 0.30000"/>
            <parent link="${left_mid_link}"/>
            <child link="${prefix}left_mid_wheel_link"/>
            <axis xyz="0.00000 0.00000 1.00000"/>
        </joint>
        <transmission name="${prefix}left_mid_wheel_joint_trans">
            <type>transmission_interface/SimpleTransmission</type>
            <joint name="${prefix}left_mid_wheel_joint">
                <hardwareInterface>hardware_interface/VelocityJointInterface</hardwareInterface>
            </joint>
            <actuator name="${prefix}left_mid_wheel_joint_motor">
                <mechanicalReduction>1.0</mechanicalReduction>
            </actuator>
        </transmission>

        <joint name="${prefix}right_back_wheel_joint" type="continuous">
            <limit lower="0" upper="0" effort="500.00000" velocity="10.00000"/>
            <origin rpy="3.14000 3.14000 0.00000" xyz="0.00000 0.00000 -0.25000"/>
            <parent link="${right_back_link}"/>
            <child link="${prefix}right_back_wheel_link"/>
            <axis xyz="0.00000 0.00000 1.00000"/>
        </joint>
        <transmission name="${prefix}right_back_wheel_joint_trans">
            <type>transmission_interface/SimpleTransmission</type>
            <joint name="${prefix}right_back_wheel_joint">
                <hardwareInterface>hardware_interface/VelocityJointInterface</hardwareInterface>
            </joint>
            <actuator name="${prefix}right_back_wheel_joint_motor">
                <mechanicalReduction>1.0</mechanicalReduction>
            </actuator>
        </transmission>
        
        <joint name="${prefix}right_front_wheel_joint" type="continuous">
            <limit lower="0" upper="0" effort="500.00000" velocity="10.00000"/>
            <origin rpy="3.14000 3.14000 0.00000" xyz="-0.00000 0.00000 -0.25000"/>
            <parent link="${right_front_link}"/>
            <child link="${prefix}right_front_wheel_link"/>
            <axis xyz="0.00000 0.00000 1.00000"/>
        </joint>
        <transmission name="${prefix}right_front_wheel_joint_trans">
            <type>transmission_interface/SimpleTransmission</type>
            <joint name="${prefix}right_front_wheel_joint">
                <hardwareInterface>hardware_interface/VelocityJointInterface</hardwareInterface>
            </joint>
            <actuator name="${prefix}right_front_wheel_joint_motor">
                <mechanicalReduction>1.0</mechanicalReduction>
            </actuator>
        </transmission>

        <joint name="${prefix}right_mid_wheel_joint" type="continuous">
            <limit lower="0" upper="0" effort="500.00000" velocity="10.00000"/>
            <origin rpy="3.14000 3.14000 0.00000" xyz="-0.00000 0.00000 -0.30000"/>
            <parent link="${right_mid_link}"/>
            <child link="${prefix}right_mid_wheel_link"/>
            <axis xyz="0.00000 0.00000 1.00000"/>
        </joint>
        <transmission name="${prefix}right_mid_wheel_joint_trans">
            <type>transmission_interface/SimpleTransmission</type>
            <joint name="${prefix}right_mid_wheel_joint">
                <hardwareInterface>hardware_interface/VelocityJointInterface</hardwareInterface>
            </joint>
            <actuator name="${prefix}right_mid_wheel_joint_motor">
                <mechanicalReduction>1.0</mechanicalReduction>
            </actuator>
        </transmission>
    </xacro:macro>
</robot>